Traceback (most recent call last):
  File "/Users/fcangemi/opt/anaconda3/lib/python3.9/site-packages/jupyter_cache/executors/utils.py", line 51, in single_nb_execution
    executenb(
  File "/Users/fcangemi/opt/anaconda3/lib/python3.9/site-packages/nbclient/client.py", line 1204, in execute
    return NotebookClient(nb=nb, resources=resources, km=km, **kwargs).execute()
  File "/Users/fcangemi/opt/anaconda3/lib/python3.9/site-packages/nbclient/util.py", line 84, in wrapped
    return just_run(coro(*args, **kwargs))
  File "/Users/fcangemi/opt/anaconda3/lib/python3.9/site-packages/nbclient/util.py", line 62, in just_run
    return loop.run_until_complete(coro)
  File "/Users/fcangemi/opt/anaconda3/lib/python3.9/asyncio/base_events.py", line 647, in run_until_complete
    return future.result()
  File "/Users/fcangemi/opt/anaconda3/lib/python3.9/site-packages/nbclient/client.py", line 663, in async_execute
    await self.async_execute_cell(
  File "/Users/fcangemi/opt/anaconda3/lib/python3.9/site-packages/nbclient/client.py", line 965, in async_execute_cell
    await self._check_raise_for_error(cell, cell_index, exec_reply)
  File "/Users/fcangemi/opt/anaconda3/lib/python3.9/site-packages/nbclient/client.py", line 862, in _check_raise_for_error
    raise CellExecutionError.from_cell_and_msg(cell, exec_reply_content)
nbclient.exceptions.CellExecutionError: An error occurred while executing the following cell:
------------------
check_inB1_list("sources.lst")
------------------

[0;31m---------------------------------------------------------------------------[0m
[0;31mFileNotFoundError[0m                         Traceback (most recent call last)
[0;32m/var/folders/cf/lj06vg8d24d6_0gnzr5lh2d40000gn/T/ipykernel_16590/2803840755.py[0m in [0;36m<module>[0;34m[0m
[0;32m----> 1[0;31m [0mcheck_inB1_list[0m[0;34m([0m[0;34m"sources.lst"[0m[0;34m)[0m[0;34m[0m[0;34m[0m[0m
[0m
[0;32m/var/folders/cf/lj06vg8d24d6_0gnzr5lh2d40000gn/T/ipykernel_16590/2243966047.py[0m in [0;36mcheck_inB1_list[0;34m(list_of_sources_file)[0m
[1;32m     38[0m [0;34m[0m[0m
[1;32m     39[0m [0;32mdef[0m [0mcheck_inB1_list[0m[0;34m([0m[0mlist_of_sources_file[0m[0;34m)[0m[0;34m:[0m[0;34m[0m[0;34m[0m[0m
[0;32m---> 40[0;31m     [0mlist_of_source[0m [0;34m=[0m [0mopen[0m[0;34m([0m[0mlist_of_sources_file[0m[0;34m,[0m [0;34m"r"[0m[0;34m)[0m[0;34m[0m[0;34m[0m[0m
[0m[1;32m     41[0m [0;34m[0m[0m
[1;32m     42[0m     [0;32mfor[0m [0msource[0m [0;32min[0m [0mlist_of_source[0m[0;34m:[0m[0;34m[0m[0;34m[0m[0m

[0;31mFileNotFoundError[0m: [Errno 2] No such file or directory: 'sources.lst'
FileNotFoundError: [Errno 2] No such file or directory: 'sources.lst'

